<?xml version="1.0"?>
{%- set model_name = "nxp_cupcar" if model_name == "NotSet" else model_name -%}
{%- set sdf_version = "1.5" if sdf_version == "NotSet" else sdf_version -%}
{%- set camera_image = "Pixy2CMUcam5" if camera_image == "NotSet" else camera_image -%}
{%- set namespace = "" if namespace == "NotSet" else namespace -%}
{%- set pixy2_cmucam5 = 1 if pixy2_cmucam5 == "NotSet" else pixy2_cmucam5 -%}
{%- set frontcam = 1 if frontcam == "NotSet" else frontcam -%}
{%- set controller = "PX4" if controller == "NotSet" else controller %}
<sdf version="{{ sdf_version }}">
  <model name="{{ model_name }}">
  	<pose>0 0 .05 0 0 0</pose>
    <static>false</static>
    <link name="{{ model_name }}_frame_link">
      <inertial>
        <pose>-0.15 0 -.1 0 0 0</pose>
        <mass>6</mass>
        <inertia>
          <ixx>0.08</ixx>
          <ixy>0.0</ixy>
          <iyy>0.03</iyy>
          <ixz>0.0</ixz>
          <iyz>0.0</iyz>
          <izz>0.08</izz>
        </inertia>
      </inertial>
    {%- if hq_frame == "1" %}
      <visual name="{{ model_name }}_frame_carbon_visual">
        <pose>-0.145 0 .146 1.57079632679 0 1.57079632679</pose>
        <geometry>
          <mesh>
            <uri>model://nxp_cupcar/meshes/CUPCarCarbonFiber.stl</uri>
            <scale>0.001 0.001 0.001</scale>
          </mesh>
        </geometry>
        <material>
          <script>
            <name>Gazebo/Black</name>
            <uri>file://media/materials/scripts/gazebo.material</uri>
          </script>
        </material>
      </visual>
      <visual name="{{ model_name }}_frame_metal_visual">
        <pose>-0.145 0 .146 1.57079632679 0 1.57079632679</pose>
        <geometry>
          <mesh>
            <uri>model://nxp_cupcar/meshes/CUPCarMetalPartsNoSteerNoScrews.stl</uri>
            <scale>0.001 0.001 0.001</scale>
          </mesh>
        </geometry>
        <material>
          <script>
            <name>Gazebo/Grey</name>
            <uri>file://media/materials/scripts/gazebo.material</uri>
          </script>
        </material>
      </visual>
      <visual name="{{ model_name }}_frame_bumper_servo_visual">
        <pose>-0.145 0 .146 1.57079632679 0 1.57079632679</pose>
        <geometry>
          <mesh>
            <uri>model://nxp_cupcar/meshes/CUPCarServoBumper.stl</uri>
            <scale>0.001 0.001 0.001</scale>
          </mesh>
        </geometry>
        <material>
          <script>
            <name>Gazebo/DarkGrey</name>
            <uri>file://media/materials/scripts/gazebo.material</uri>
          </script>
        </material>
      </visual>
    {%- endif %}
    {%- if hq_frame != "1" %}
      <visual name="{{ model_name }}_inertial_frame">
        <pose>-0.15 0 -.1 0 0 0</pose>
        <geometry>
          <sphere>
            <radius>0.06</radius>
          </sphere>
        </geometry>
        <material>
          <script>
            <!-- <name>Gazebo/Red</name>
            <uri>file://media/materials/scripts/gazebo.material</uri> -->
          </script>
        </material>
      </visual>  
      <visual name="{{ model_name }}_frame_collision_visual">
        <pose>0 0 0 0 0 1.57079632679</pose>
        <geometry>
          <mesh>
            <uri>model://nxp_cupcar/meshes/finalLOGO.dae</uri>
            <scale>1.0 1.0 1.0</scale>
          </mesh>
        </geometry>
        <material>
          <script>
            <!-- <name>Gazebo/DarkGrey</name>
            <uri>file://media/materials/scripts/gazebo.material</uri> -->
          </script>
        </material>
      </visual>
    {%- endif %}
      <collision name="{{ model_name }}_frame_collision">
        <pose>-.11 0 .008 0 0 0</pose>
        <geometry>
          <box>
            <size>.3 .05 .047</size>
          </box>
        </geometry>
      </collision>
      <!--contact sensor test-->
      <sensor name="car_contact" type="contact">
        <contact>
          <collision>{{ model_name }}_frame_collision</collision>
        </contact>
        <update_rate>5</update_rate>
        <alwaysOn>true</alwaysOn>
      </sensor>
    </link>
    <link name="{{ model_name }}_front_left_wheel_link">
      <pose>-.04 0.07 -.0055 0 0 1.57079632679</pose>
      <inertial>
        <pose>0 0 0 0 0 0</pose>
        <mass>.05</mass>
        <inertia>
          <ixx>0.015</ixx>
          <ixy>0.0</ixy>
          <iyy>0.007</iyy>
          <ixz>0.0</ixz>
          <iyz>0.0</iyz>
          <izz>0.007</izz>
        </inertia>
      </inertial>
      <collision name="{{ model_name }}_front_left_wheel_collision">
        <pose>0 0 0 0 1.57079632679 0</pose>
        <geometry>
          <sphere>
            <radius>0.033</radius>
          </sphere>
        </geometry>
        <max_contacts>1</max_contacts>
        <surface>
          <friction>
            <ode>
              <mu>0.5</mu>
              <mu2>3.0</mu2>
              <fdir1>2 .5 .5</fdir1>
              <slip1>0.0</slip1>
              <slip2>0.0</slip2>
            </ode>
          </friction>
          <contact>
            <ode>
              <min_depth>0.001</min_depth>
              <kp>1e9</kp>
            </ode>
          </contact>
        </surface>
      </collision>
    {%- if hq_wheel != "1" %}
      <visual name="{{ model_name }}_front_left_wheel_collision_visual">
        <pose>0 0 0 0 1.57079632679 0</pose>
        <geometry>
          <cylinder>
            <radius>0.033</radius>
            <length>0.024</length>
          </cylinder>
        </geometry>
        <material>
          <script>
            <name>Gazebo/DarkGrey</name>
            <uri>file://media/materials/scripts/gazebo.material</uri>
          </script>
        </material>
      </visual>
    {%- endif %}
    {%- if hq_wheel == "1" %}
      <visual name="{{ model_name }}_front_left_wheel_visual">
        <pose>0 0 0 0 0 3.141592653589793238</pose>
        <geometry>
          <mesh>
            <uri>model://nxp_cupcar/meshes/LeftWheel.stl</uri>
          </mesh>
        </geometry>
        <material>
          <script>
            <name>Gazebo/Grey</name>
            <uri>file://media/materials/scripts/gazebo.material</uri>
          </script>          
        </material>
      </visual>
    {%- endif %}
      <gravity>1</gravity>
      <velocity_decay/>
    </link>
    <link name="{{ model_name }}_front_right_wheel_link">
      <pose>-.04 -0.07 -.0055 0 0 1.57079632679</pose>
      <inertial>
        <pose>0 0 0 0 0 0</pose>
        <mass>.05</mass>
        <inertia>
          <ixx>0.015</ixx>
          <ixy>0.0</ixy>
          <iyy>0.007</iyy>
          <ixz>0.0</ixz>
          <iyz>0.0</iyz>
          <izz>0.007</izz>
        </inertia>
      </inertial>
      <collision name="{{ model_name }}_front_right_wheel_collision">
        <pose>0 0 0 0 1.57079632679 0</pose>
        <geometry>
          <cylinder>
            <radius>0.033</radius>
            <length>0.022</length>
          </cylinder>
        </geometry>
        <max_contacts>1</max_contacts>
        <surface>
          <friction>
            <ode>
              <mu>0.5</mu>
              <mu2>3.0</mu2>
              <fdir1>2 .5 .5</fdir1>
              <slip1>0.0</slip1>
              <slip2>0.0</slip2>
            </ode>
          </friction>
          <contact>
            <ode>
              <min_depth>0.001</min_depth>
              <kp>1e9</kp>
            </ode>
          </contact>
        </surface>
      </collision>
    {%- if hq_wheel != "1" %}
      <visual name="{{ model_name }}_front_right_wheel_collision_visual">
        <pose>0 0 0 0 1.57079632679 0</pose>
        <geometry>
          <cylinder>
            <radius>0.033</radius>
            <length>0.024</length>
          </cylinder>
        </geometry>
        <material>
          <script>
            <name>Gazebo/DarkGrey</name>
            <uri>file://media/materials/scripts/gazebo.material</uri>
          </script>
        </material>
      </visual>
    {%- endif %}
    {%- if hq_wheel == "1" %}
      <visual name="{{ model_name }}_front_right_wheel_visual">
        <pose>0 0 0 0 0 0</pose>
        <geometry>
          <mesh>
            <uri>model://nxp_cupcar/meshes/RightWheel.stl</uri>
          </mesh>
        </geometry>
        <material>
          <script>
            <name>Gazebo/Grey</name>
            <uri>file://media/materials/scripts/gazebo.material</uri>
          </script>          
        </material>
      </visual>
    {%- endif %}
      <gravity>1</gravity>
      <velocity_decay/>
    </link>
    <link name="{{ model_name }}_rear_left_wheel_link">
      <pose>-.213 0.07 -.0055 0 0 1.57079632679</pose>
      <inertial>
        <pose>0 0 0 0 0 0</pose>
        <mass>.05</mass>
        <inertia>
          <ixx>0.015</ixx>
          <ixy>0.0</ixy>
          <iyy>0.007</iyy>
          <ixz>0.0</ixz>
          <iyz>0.0</iyz>
          <izz>0.007</izz>
        </inertia>
      </inertial>
      <collision name="{{ model_name }}_rear_left_wheel_collision">
        <pose>0 0 0 0 1.57079632679 0</pose>
        <geometry>
          <cylinder>
            <radius>0.033</radius>
            <length>0.022</length>
          </cylinder>
        </geometry>
        <max_contacts>1</max_contacts>
        <surface>
          <friction>
            <ode>
              <mu>4.0</mu>
              <mu2>2.0</mu2>
              <fdir1>2 .5 .5</fdir1>
              <slip1>0.0</slip1>
              <slip2>0.0</slip2>
            </ode>
          </friction>
          <contact>
            <ode>
              <min_depth>0.001</min_depth>
              <kp>1e9</kp>
            </ode>
          </contact>
        </surface>
      </collision>
    {%- if hq_wheel != "1" %}
      <visual name="{{ model_name }}_rear_left_wheel_collision_visual">
        <pose>0 0 0 0 1.57079632679 0</pose>
        <geometry>
          <cylinder>
            <radius>0.033</radius>
            <length>0.024</length>
          </cylinder>
        </geometry>
        <material>
          <script>
            <name>Gazebo/DarkGrey</name>
            <uri>file://media/materials/scripts/gazebo.material</uri>
          </script>
        </material>
      </visual>
    {%- endif %}
    {%- if hq_wheel == "1" %}
      <visual name="{{ model_name }}_rear_left_wheel_visual">
        <pose>0 0 0 0 0 3.141592653589793238</pose>
        <geometry>
          <mesh>
            <uri>model://nxp_cupcar/meshes/LeftWheel.stl</uri>
          </mesh>
        </geometry>
        <material>
          <script>
            <name>Gazebo/Grey</name>
            <uri>file://media/materials/scripts/gazebo.material</uri>
          </script>
        </material>
      </visual>
    {%- endif %}
      <gravity>1</gravity>
      <velocity_decay/>
    </link>
    <link name="{{ model_name }}_rear_right_wheel_link">
      <pose>-.213 -0.07 -.0055 0 0 1.57079632679</pose>
      <inertial>
        <pose>0 0 0 0 0 0</pose>
        <mass>.05</mass>
        <inertia>
          <ixx>0.015</ixx>
          <ixy>0.0</ixy>
          <iyy>0.007</iyy>
          <ixz>0.0</ixz>
          <iyz>0.0</iyz>
          <izz>0.007</izz>
        </inertia>
      </inertial>
      <collision name="{{ model_name }}_rear_right_wheel_collision">
        <pose>0 0 0 0 1.57079632679 0</pose>
        <geometry>
          <sphere>
            <radius>0.033</radius>
          </sphere>
        </geometry>
        <max_contacts>1</max_contacts>
        <surface>
          <friction>
            <ode>
              <mu>4.0</mu>
              <mu2>2.0</mu2>
              <fdir1>2 .5 .5</fdir1>
              <slip1>0.0</slip1>
              <slip2>0.0</slip2>
            </ode>
          </friction>
          <contact>
            <ode>
              <min_depth>0.001</min_depth>
              <kp>1e9</kp>
            </ode>
          </contact>
        </surface>
      </collision>
    {%- if hq_wheel != "1" %}
      <visual name="{{ model_name }}_rear_right_wheel_collision_visual">
        <pose>0 0 0 0 1.57079632679 0</pose>
        <geometry>
          <cylinder>
            <radius>0.033</radius>
            <length>0.024</length>
          </cylinder>
        </geometry>
        <material>
          <script>
            <name>Gazebo/DarkGrey</name>
            <uri>file://media/materials/scripts/gazebo.material</uri>
          </script>
        </material>
      </visual>
    {%- endif %}
    {%- if hq_wheel == "1" %}
      <visual name="{{ model_name }}_rear_right_wheel_visual">
        <pose>0 0 0 0 0 0</pose>
        <geometry>
          <mesh>
            <uri>model://nxp_cupcar/meshes/RightWheel.stl</uri>
          </mesh>
        </geometry>
        <material>
          <script>
            <name>Gazebo/Grey</name>
            <uri>file://media/materials/scripts/gazebo.material</uri>
          </script>
        </material>
      </visual>
    {%- endif %}
      <gravity>1</gravity>
      <velocity_decay/>
    </link>
  {%- if pixy2_cmucam5 == 1 %}
    <link name="{{ camera_image }}_link">
      <pose>-.09 0 .32 0 1.0 0</pose>
      <visual name="{{ camera_image }}_visual">
        <pose>0 0 0 1.57079632679 0 1.57079632679</pose>
        <geometry>
          <mesh>
            <uri>model://pixy2_cmucam5/meshes/Pixy2CMUcam5.obj</uri>
            <scale>.001 .001 .001</scale>
          </mesh>
        </geometry>
      </visual>
      <!--Image sensor: Aptina MT9M114-->
      <sensor type="camera" name="{{ camera_image }}">
        <always_on>true</always_on>
        <update_rate>30.0</update_rate>
        <camera name="head">
          <!--horizontal_fov should be 1.0472 but need it wider with lens-->
          <horizontal_fov>1.5</horizontal_fov>
          <image>
            <width>1296</width>
            <height>936</height> <!--should be 976 but need to be 936 for 18x scale-->
            <format>R8G8B8</format>
          </image>
          <clip>
            <near>0.01</near>
            <far>100</far>
          </clip>
          <lens>
            <type>gnomonical</type>
            <scale_to_hfov>1</scale_to_hfov>
          </lens>
          <noise>
            <type>gaussian</type>
            <mean>0.0</mean>
            <stddev>0.007</stddev>
          </noise>
        </camera>
        <plugin name='{{ camera_image }}_camera_controller' filename='libgazebo_ros_camera.so'>
          <robotNamespace>{{ namespace }}</robotNamespace>
          <cameraName>{{ camera_image }}</cameraName>
          <imageTopicName>image_raw</imageTopicName>
          <cameraInfoTopicName>camera_info</cameraInfoTopicName>
          <frameName>camera_link</frameName>
          <hackBaseline>0.07</hackBaseline>
          <distortionK1>0.0</distortionK1>
          <distortionK2>0.0</distortionK2>
          <distortionK3>0.0</distortionK3>
          <distortionT1>0.0</distortionT1>
          <distortionT2>0.0</distortionT2>
        </plugin>
      </sensor>
    </link>
    <joint name="pixy2_cmucam5_joint" type="fixed">
      <child>{{ camera_image }}_link</child>
      <parent>{{ model_name }}_frame_link</parent>
    </joint>
  {%- endif %}
  
  
    <!-- this is our front facing camera -->
    <link name="frontcam_link">
      <pose>-.09 0 .1 0 0 0</pose>
      <visual name="frontcam_visual">
        <pose>0 0 0 1.57079632679 0 1.57079632679</pose>
        <geometry>
          <mesh>
            <uri>model://frontcam/meshes/frontcam.obj</uri>
            <scale>.001 .001 .001</scale>
          </mesh>
        </geometry>
      </visual>
      <!--Image sensor: Aptina MT9M114-->
      <sensor type="camera" name="frontcam">
        <always_on>true</always_on>
        <update_rate>30.0</update_rate>
        <camera name="head">
          <!--horizontal_fov should be 1.0472 but need it wider with lens-->
          <horizontal_fov>1.5</horizontal_fov>
          <image>
            <width>1296</width>
            <height>936</height> <!--should be 976 but need to be 936 for 18x scale-->
            <format>R8G8B8</format>
          </image>
          <clip>frontcam
            <near>0.02</near>
            <far>1</far>
          </clip>
          <lens>
            <type>gnomonical</type>
            <scale_to_hfov>1</scale_to_hfov>
          </lens>
          <noise>
            <type>gaussian</type>
            <mean>0.0</mean>
            <stddev>0.007</stddev>
          </noise>
        </camera>
        <plugin name='frontcam_camera_controller' filename='libgazebo_ros_camera.so'>
          <robotNamespace>{{ namespace }}</robotNamespace>
          <cameraName>frontcam</cameraName>
          <imageTopicName>image_raw</imageTopicName>
          <cameraInfoTopicName>camera_info</cameraInfoTopicName>
          <frameName>camera_link</frameName>
          <hackBaseline>0.07</hackBaseline>
          <distortionK1>0.0</distortionK1>
          <distortionK2>0.0</distortionK2>
          <distortionK3>0.0</distortionK3>
          <distortionT1>0.0</distortionT1>
          <distortionT2>0.0</distortionT2>
        </plugin>
      </sensor>
    </link>
    <joint name="frontcam_joint" type="fixed">
      <child>frontcam_link</child>
      <parent>{{ model_name }}_frame_link</parent>
    </joint>
  
  
  
  
  
  {%- if controller == "PX4" %}
    <link name="{{ model_name }}_front_right_wheel_steering_link">
      <pose>-.04 -0.06 -.0055 0 0 0</pose>
      <inertial>
        <mass>0.1</mass>
        <inertia>
          <ixx>0.001</ixx>
          <ixy>0.0</ixy>
          <iyy>0.001</iyy>
          <ixz>0.0</ixz>
          <iyz>0.0</iyz>
          <izz>0.001</izz>
        </inertia>
      </inertial>
      <gravity>1</gravity>
      <velocity_decay/>
    </link>
    <link name="{{ model_name }}_front_left_wheel_steering_link">
      <pose>-.04 0.06 -.0055 0 0 0</pose>
      <inertial>
        <mass>0.1</mass>
        <inertia>
          <ixx>0.001</ixx>
          <ixy>0.0</ixy>
          <iyy>0.001</iyy>
          <ixz>0.0</ixz>
          <iyz>0.0</iyz>
          <izz>0.001</izz>
        </inertia>
      </inertial>
      <gravity>1</gravity>
      <velocity_decay/>
    </link>
    <joint type="revolute" name="{{ model_name }}_front_left_steering_joint">
      <child>{{ model_name }}_front_left_wheel_steering_link</child>
      <parent>{{ model_name }}_frame_link</parent>
      <axis>
        <xyz>0 0 1</xyz>
        <limit>
          <lower>-0.7727</lower>
          <upper>0.7727</upper>
        </limit>
        <dynamics>
          <friction>.1</friction>
          <damping>0.5</damping>
          <spring_reference>0</spring_reference>
          <spring_stiffness>0</spring_stiffness>
        </dynamics>
        <use_parent_model_frame>true</use_parent_model_frame>
      </axis>
    </joint>
    <joint type="revolute" name="{{ model_name }}_front_right_steering_joint">
      <child>{{ model_name }}_front_right_wheel_steering_link</child>
      <parent>{{ model_name }}_frame_link</parent>
      <axis>
        <xyz>0 0 1</xyz>
        <limit>
          <lower>-0.7727</lower>
          <upper>0.7727</upper>
        </limit>
        <dynamics>
          <friction>.1</friction>
          <damping>0.5</damping>
          <spring_reference>0</spring_reference>
          <spring_stiffness>0</spring_stiffness>
        </dynamics>
        <use_parent_model_frame>true</use_parent_model_frame>
      </axis>
    </joint>
    <joint type="revolute" name="{{ model_name }}_front_left_wheel_joint">
      <child>{{ model_name }}_front_left_wheel_link</child>
      <parent>{{ model_name }}_front_left_wheel_steering_link</parent>
      <axis>
        <xyz>0 1 0</xyz>
        <limit>
          <lower>-1e+16</lower>
          <upper>1e+16</upper>
        </limit>
        <dynamics>
          <spring_reference>0</spring_reference>
          <spring_stiffness>0</spring_stiffness>
        </dynamics>
        <use_parent_model_frame>1</use_parent_model_frame>
      </axis>
    </joint>
    <joint type="revolute" name="{{ model_name }}_front_right_wheel_joint">
      <child>{{ model_name }}_front_right_wheel_link</child>
      <parent>{{ model_name }}_front_right_wheel_steering_link</parent>
      <axis>
        <xyz>0 1 0</xyz>
        <limit>
          <lower>-1e+16</lower>
          <upper>1e+16</upper>
        </limit>
        <dynamics>
          <spring_reference>0</spring_reference>
          <spring_stiffness>0</spring_stiffness>
        </dynamics>
        <use_parent_model_frame>1</use_parent_model_frame>
      </axis>
    </joint>
    <joint type="revolute" name="{{ model_name }}_rear_left_wheel_joint">
      <child>{{ model_name }}_rear_left_wheel_link</child>
      <parent>{{ model_name }}_frame_link</parent>
      <axis>
        <xyz>0 1 0</xyz>
        <limit>
          <lower>-1e+16</lower>
          <upper>1e+16</upper>
        </limit>
        <dynamics>
          <spring_reference>0</spring_reference>
          <spring_stiffness>0</spring_stiffness>
        </dynamics>
        <use_parent_model_frame>1</use_parent_model_frame>
      </axis>
    </joint>
    <joint type="revolute" name="{{ model_name }}_rear_right_wheel_joint">
      <child>{{ model_name }}_rear_right_wheel_link</child>
      <parent>{{ model_name }}_frame_link</parent>
      <axis>
        <xyz>0 1 0</xyz>
        <limit>
          <lower>-1e+16</lower>
          <upper>1e+16</upper>
        </limit>
        <dynamics>
          <spring_reference>0</spring_reference>
          <spring_stiffness>0</spring_stiffness>
        </dynamics>
        <use_parent_model_frame>1</use_parent_model_frame>
      </axis>
    </joint>
    <link name="{{ model_name }}/imu_link">
      <pose>-.15 0 .05 0 0 0</pose>
      <inertial>
        <pose>0 0 0 0 0 0</pose>
        <mass>0.015</mass>
        <inertia>
          <ixx>1e-05</ixx>
          <ixy>0</ixy>
          <ixz>0</ixz>
          <iyy>1e-05</iyy>
          <iyz>0</iyz>
          <izz>1e-05</izz>
        </inertia>
      </inertial>
      <gravity>1</gravity>
      <velocity_decay/>
    </link>
    <joint name="{{ model_name }}/imu_joint" type="revolute">
      <child>{{ model_name }}/imu_link</child>
      <parent>{{ model_name }}_frame_link</parent>
      <axis>
        <xyz>1 0 0</xyz>
        <limit>
          <lower>0</lower>
          <upper>0</upper>
          <effort>0</effort>
          <velocity>0</velocity>
        </limit>
        <dynamics>
          <spring_reference>0</spring_reference>
          <spring_stiffness>0</spring_stiffness>
        </dynamics>
        <use_parent_model_frame>1</use_parent_model_frame>
      </axis>
    </joint>
    <model name="gps0">
      <link name="link">
        <pose>-.15 0 .05 0 0 0</pose>
        <inertial>
          <pose>0 0 0 0 0 0</pose>
          <mass>0.01</mass>
          <inertia>
            <ixx>2.1733e-06</ixx>
            <ixy>0</ixy>
            <ixz>0</ixz>
            <iyy>2.1733e-06</iyy>
            <iyz>0</iyz>
            <izz>1.8e-07</izz>
          </inertia>
        </inertial>
        <visual name="visual">
          <geometry>
            <cylinder>
              <radius>0.01</radius>
              <length>0.002</length>
            </cylinder>
          </geometry>
          <material>
            <script>
              <name>Gazebo/Black</name>
              <uri>__default__</uri>
            </script>
          </material>
        </visual>
        <sensor name="gps" type="gps">
          <pose>0 0 0 0 0 0</pose>
          <plugin name='gps_plugin' filename='libgazebo_gps_plugin.so'>
            <robotNamespace/>
            <gpsNoise>1</gpsNoise>
            <gpsXYRandomWalk>2.0</gpsXYRandomWalk>
            <gpsZRandomWalk>4.0</gpsZRandomWalk>
            <gpsXYNoiseDensity>0.0002</gpsXYNoiseDensity>
            <gpsZNoiseDensity>0.0004</gpsZNoiseDensity>
            <gpsVXYNoiseDensity>0.2</gpsVXYNoiseDensity>
            <gpsVZNoiseDensity>0.4</gpsVZNoiseDensity>
          </plugin>
        </sensor>
      </link>
    </model>
    <joint name="gps0_joint" type="fixed">
      <parent>{{ model_name }}_frame_link</parent>
      <child>gps0::link</child>
    </joint>  
    <plugin name='gazebo_imu_plugin' filename='libgazebo_imu_plugin.so'>
      <robotNamespace>{{ namespace }}</robotNamespace>
      <linkName>{{ model_name }}/imu_link</linkName>
      <imuTopic>/imu</imuTopic>
      <gyroscopeNoiseDensity>0.0003394</gyroscopeNoiseDensity>
      <gyroscopeRandomWalk>3.8785e-05</gyroscopeRandomWalk>
      <gyroscopeBiasCorrelationTime>1000.0</gyroscopeBiasCorrelationTime>
      <gyroscopeTurnOnBiasSigma>0.0087</gyroscopeTurnOnBiasSigma>
      <accelerometerNoiseDensity>0.004</accelerometerNoiseDensity>
      <accelerometerRandomWalk>0.006</accelerometerRandomWalk>
      <accelerometerBiasCorrelationTime>300.0</accelerometerBiasCorrelationTime>
      <accelerometerTurnOnBiasSigma>0.196</accelerometerTurnOnBiasSigma>
    </plugin>
    <plugin name='groundtruth_plugin' filename='libgazebo_groundtruth_plugin.so'>
      <robotNamespace>{{ namespace }}</robotNamespace>
    </plugin>
    <plugin name='magnetometer_plugin' filename='libgazebo_magnetometer_plugin.so'>
      <robotNamespace>{{ namespace }}</robotNamespace>
      <pubRate>100</pubRate>
      <noiseDensity>0.0004</noiseDensity>
      <randomWalk>6.4e-06</randomWalk>
      <biasCorrelationTime>600</biasCorrelationTime>
      <magTopic>/mag</magTopic>
    </plugin>
    <plugin name='barometer_plugin' filename='libgazebo_barometer_plugin.so'>
      <robotNamespace>{{ namespace }}</robotNamespace>
      <pubRate>50</pubRate>
      <baroTopic>/baro</baroTopic>
      <baroDriftPaPerSec>0</baroDriftPaPerSec>
    </plugin>
    <plugin name='mavlink_interface' filename='libgazebo_mavlink_interface.so'>
      <robotNamespace>{{ namespace }}</robotNamespace>
      <imuSubTopic>/imu</imuSubTopic>
      <magSubTopic>/mag</magSubTopic>
      <baroSubTopic>/baro</baroSubTopic>
      <mavlink_addr>INADDR_ANY</mavlink_addr>
      <mavlink_udp_port>{{ mavlink_udp_port }}</mavlink_udp_port>
      <mavlink_tcp_port>{{ mavlink_tcp_port }}</mavlink_tcp_port>
      <serialEnabled>{{ serial_enabled }}</serialEnabled>
      <serialDevice>{{ serial_device }}</serialDevice>
      <baudRate>{{ serial_baudrate }}</baudRate>
      <qgc_addr>INADDR_ANY</qgc_addr>
      <qgc_udp_port>{{ qgc_udp_port }}</qgc_udp_port>
      <sdk_addr>INADDR_ANY</sdk_addr>
      <sdk_udp_port>{{ sdk_udp_port }}</sdk_udp_port>
      <hil_mode>{{ hil_mode }}</hil_mode>
      <hil_state_level>0</hil_state_level>
      <send_vision_estimation>0</send_vision_estimation>
      <send_odometry>1</send_odometry>
      <enable_lockstep>{{ enable_lockstep }}</enable_lockstep>
      <use_tcp>1</use_tcp>
      <motorSpeedCommandPubTopic>/gazebo/command/motor_speed</motorSpeedCommandPubTopic>
      <control_channels>
        <channel name="{{ model_name }}_rear_left_wheel_drive">
          <input_index>5</input_index>
          <input_offset>0</input_offset>
          <input_scaling>60</input_scaling>
          <zero_position_disarmed>0</zero_position_disarmed>
          <zero_position_armed>0</zero_position_armed>
          <joint_control_type>velocity</joint_control_type>
          <joint_name>{{ model_name }}_rear_left_wheel_joint</joint_name>
          <joint_control_pid>
            <p>0.1</p>
            <i>0</i>
            <d>0</d>
            <iMax>800</iMax>
            <iMin>-800</iMin>
            <cmdMax>1600</cmdMax>
            <cmdMin>-1600</cmdMin>
          </joint_control_pid>
        </channel>
        <channel name="{{ model_name }}_rear_right_wheel_drive">
          <input_index>6</input_index>
          <input_offset>0</input_offset>
          <input_scaling>60</input_scaling>
          <zero_position_disarmed>0</zero_position_disarmed>
          <zero_position_armed>0</zero_position_armed>
          <joint_control_type>velocity</joint_control_type>
          <joint_name>{{ model_name }}_rear_right_wheel_joint</joint_name>
          <joint_control_pid>
            <p>0.1</p>
            <i>0</i>
            <d>0</d>
            <iMax>800</iMax>
            <iMin>-800</iMin>
            <cmdMax>1600</cmdMax>
            <cmdMin>-1600</cmdMin>
          </joint_control_pid>
        </channel>
        <channel name="{{ model_name }}_left_wheel_steering">
          <input_index>0</input_index>
          <input_offset>0</input_offset>
          <input_scaling>-0.7</input_scaling>
          <zero_position_disarmed>0</zero_position_disarmed>
          <zero_position_armed>0</zero_position_armed>
          <joint_control_type>position</joint_control_type>
          <joint_name>{{ model_name }}_front_left_steering_joint</joint_name>
          <joint_control_pid>
            <p>5.0</p>
            <i>0</i>
            <d>0</d>
            <iMax>40</iMax>
            <iMin>-40</iMin>
            <cmdMax>35</cmdMax>
            <cmdMin>-35</cmdMin>
          </joint_control_pid>
        </channel>
        <channel name="{{ model_name }}_right_wheel_steering">
          <input_index>1</input_index>
          <input_offset>0</input_offset>
          <input_scaling>-0.7</input_scaling>
          <zero_position_disarmed>0</zero_position_disarmed>
          <zero_position_armed>0</zero_position_armed>
          <joint_control_type>position</joint_control_type>
          <joint_name>{{ model_name }}_front_right_steering_joint</joint_name>
          <joint_control_pid>
            <p>5.0</p>
            <i>0</i>
            <d>0</d>
            <iMax>40</iMax>
            <iMin>-40</iMin>
            <cmdMax>35</cmdMax>
            <cmdMin>-35</cmdMin>
          </joint_control_pid>
        </channel>
      </control_channels>
    </plugin>
  {%- endif %}
  {%- if controller == "ROS2" %}
    <link name="{{ model_name }}_steering_wheel_link">
      <pose>-0.05 0 0.06 -1.302101 0 1.57</pose>
      <inertial>
        <mass>0.01</mass>
        <inertia>
          <ixx>0.0014583300</ixx>
          <ixy>0</ixy>
          <ixz>0</ixz>
          <iyy>0.0014583300</iyy>
          <iyz>0</iyz>
          <izz>0.0012500000</izz>
        </inertia>
      </inertial>
    </link>
    <joint type="universal" name="{{ model_name }}_front_left_combined_joint">
      <child>{{ model_name }}_front_left_wheel_link</child>
      <parent>{{ model_name }}_frame_link</parent>
      <axis>
        <xyz>0 0 1</xyz>
        <limit>
          <lower>-0.8727</lower>
          <upper>0.8727</upper>
        </limit>
        <dynamics>
          <damping>0.5</damping>
        </dynamics>
      </axis>
      <axis2>
        <xyz>1 0 0</xyz>
        <dynamics>
          <friction>0.05</friction>
        </dynamics>
      </axis2>
    </joint>
    <joint type="universal" name="{{ model_name }}_front_right_combined_joint">
      <child>{{ model_name }}_front_right_wheel_link</child>
      <parent>{{ model_name }}_frame_link</parent>
      <axis>
        <xyz>0 0 1</xyz>
        <limit>
          <lower>-0.8727</lower>
          <upper>0.8727</upper>
        </limit>
        <dynamics>
          <damping>0.5</damping>
        </dynamics>
      </axis>
      <axis2>
        <xyz>1 0 0</xyz>
        <dynamics>
          <friction>0.05</friction>
        </dynamics>
      </axis2>
    </joint>
    <joint type="revolute" name="{{ model_name }}_rear_left_wheel_joint">
      <child>{{ model_name }}_rear_left_wheel_link</child>
      <parent>{{ model_name }}_frame_link</parent>
      <axis>
        <xyz>1 0 0</xyz>
        <dynamics>
          <friction>0.2</friction>
        </dynamics>
      </axis>
    </joint>
    <joint type="revolute" name="{{ model_name }}_rear_right_wheel_joint">
      <child>{{ model_name }}_rear_right_wheel_link</child>
      <parent>{{ model_name }}_frame_link</parent>
      <axis>
        <xyz>1 0 0</xyz>
        <dynamics>
          <friction>0.2</friction>
        </dynamics>
      </axis>
    </joint>
    <joint name="{{ model_name }}_steering_wheel_joint" type="revolute">
      <pose>-0.002 0 0 0 0 0</pose>
      <parent>{{ model_name }}_frame_link</parent>
      <child>{{ model_name }}_steering_wheel_link</child>
      <axis>
        <xyz>-0.964118 0.000768 0.265556</xyz>
        <limit>
          <lower>-7.85</lower>
          <upper>7.85</upper>
        </limit>
        <dynamics>
          <damping>1.0</damping>
        </dynamics>
        <use_parent_model_frame>true</use_parent_model_frame>
      </axis>
      <physics>
        <ode>
          <cfm_damping>1</cfm_damping>
        </ode>
      </physics>
    </joint>
    <plugin name='ackermann_drive' filename='libgazebo_ros_ackermann_drive.so'>
      <ros>
        <namespace>{{ namespace }}</namespace>
      </ros>
      <update_rate>100.0</update_rate>
      <front_left_joint>{{ model_name }}_front_left_combined_joint</front_left_joint>
      <front_right_joint>{{ model_name }}_front_right_combined_joint</front_right_joint>
      <rear_left_joint>{{ model_name }}_rear_left_wheel_joint</rear_left_joint>
      <rear_right_joint>{{ model_name }}_rear_right_wheel_joint</rear_right_joint>
      <left_steering_joint>{{ model_name }}_front_left_combined_joint</left_steering_joint>
      <right_steering_joint>{{ model_name }}_front_right_combined_joint</right_steering_joint>
      <steering_wheel_joint>{{ model_name }}_steering_wheel_joint</steering_wheel_joint>
      <max_steer>0.6458</max_steer>
      <max_steering_angle>7.85</max_steering_angle>
      <max_speed>5</max_speed>
      <left_steering_pid_gain>15 0 1</left_steering_pid_gain>
      <left_steering_i_range>0 0</left_steering_i_range>
      <right_steering_pid_gain>15 0 1</right_steering_pid_gain>
      <right_steering_i_range>0 0</right_steering_i_range>
      <linear_velocity_pid_gain>0.5 0 .1</linear_velocity_pid_gain>
      <linear_velocity_i_range>0 0</linear_velocity_i_range>
      <publish_odom>true</publish_odom>
      <publish_odom_tf>true</publish_odom_tf>
      <publish_wheel_tf>true</publish_wheel_tf>
      <publish_distance>true</publish_distance>
      <odometry_frame>odom</odometry_frame>
      <robot_base_frame>{{ model_name }}_frame_link</robot_base_frame>
    </plugin>
  {%- endif %}
  </model>
</sdf>
